<?xml version="1.0"?>
<!--
This is a URDF file for the Punyo robot.
The robot has a torso and two arms. Each arm is covered by six floatie 2.0s and one floatie 1.0,
and the end-effector is a bubble paw. This is intended as
a high-fidelity model of the robot.

The continuous joints are limited by hard mechanical stops
at the limits below. The revolute joint are not mechanically
limited, thus using the manufacturer's limits.
The limits are duplicated from models/robot/gen_punyo_jaco_arm.py,
thus, they should be kept in sync.
-->
<robot xmlns:drake='http://drake.mit.edu' name="punyo">
  <link name="head">
    <visual name='neck_visual'>
      <origin rpy="0 0 -1.57" xyz="-0.06 0 0.47"/>
      <geometry>
        <mesh filename="meshes/A4_Punyo_Neck.obj"/>
      </geometry>
      <material>
        <color rgba="0.1788232 0.1788232 0.1788232 1"/>
      </material>
    </visual>
    <visual name='head_white_visual'>
      <origin rpy="0 0 -1.57" xyz="-0.06 0 0.47"/>
      <geometry>
        <mesh filename="meshes/A4_Punyo_Head_white.obj"/>
      </geometry>
      <material>
        <color rgba="0.812 0.039 0.039 1"/>
      </material>
    </visual>
    <visual name='head_black_visual'>
      <origin rpy="0 0 -1.57" xyz="-0.06 0 0.47"/>
      <geometry>
        <mesh filename="meshes/A4_Punyo_Head_black.obj"/>
      </geometry>
      <material>
        <color rgba="0.1788232 0.1788232 0.1788232 1"/>
      </material>
    </visual>
    <collision name='neck_collision'>
      <origin rpy="0 0 0" xyz="-0.03 0 0.49"/>
      <geometry>
        <cylinder length="0.05" radius="0.055"/>
      </geometry>
      <drake:proximity_properties>
        <drake:mesh_resolution_hint value="0.04"/>
        <drake:rigid_hydroelastic/>
        <drake:hunt_crossley_dissipation value="5"/>
        <drake:mu_static value="0.5"/>
      </drake:proximity_properties>
    </collision>
    <collision name='head_collision'>
      <origin rpy="0 0 0" xyz="0 0 0.655"/>
      <geometry>
        <sphere radius="0.16"/>
      </geometry>
      <drake:proximity_properties>
        <drake:mesh_resolution_hint value="0.04"/>
        <drake:rigid_hydroelastic/>
        <drake:hunt_crossley_dissipation value="5"/>
        <drake:mu_static value="0.5"/>
      </drake:proximity_properties>
    </collision>
  </link>
  <joint name="head_torso_link" type="fixed">
    <parent link="torso"/>
    <child link="head"/>
    <axis xyz="0 0 0"/>
    <limit effort="2000" lower="0" upper="0" velocity="1"/>
    <origin rpy="0 0 0" xyz="0 0 0"/>
    <dynamics damping="0.0" friction="0.0"/>
  </joint>
  <link name="torso">
    <visual name='chest_left_visual'>
      <geometry>
        <mesh filename="meshes/MA-081-PT-0003_chest_left.obj"/>
      </geometry>
      <material>
        <color rgba="0.812 0.039 0.039 1"/>
      </material>
    </visual>
    <visual name='chest_right_visual'>
      <geometry>
        <mesh filename="meshes/MA-081-PT-0003_chest_right.obj"/>
      </geometry>
      <material>
        <color rgba="0.812 0.039 0.039 1"/>
      </material>
    </visual>
    <visual name='chest_middle_visual'>
      <geometry>
        <mesh filename="meshes/MA-081-PT-0003_chest_middle.obj"/>
      </geometry>
      <material>
        <color rgba="0.812 0.039 0.039 1"/>
      </material>
    </visual>
    <!-- Add modularized collision geoms for the chest. -->
    <collision name='chest_left_collision'>
      <geometry>
        <mesh filename="meshes/MA-081-PT-0003_chest_left.obj"/>
      </geometry>
    </collision>
    <collision name='chest_middle_collision'>
      <geometry>
        <mesh filename="meshes/MA-081-PT-0003_chest_middle.vtk"/>
      </geometry>
      <drake:proximity_properties>
        <drake:mesh_resolution_hint value="0.04"/>
        <drake:rigid_hydroelastic/>
        <drake:hunt_crossley_dissipation value="5"/>
        <drake:mu_static value="0.5"/>
      </drake:proximity_properties>
    </collision>
    <collision name='chest_right_collision'>
      <geometry>
        <mesh filename="meshes/MA-081-PT-0003_chest_right.obj"/>
      </geometry>
    </collision>
  </link>
  <link name="j2s7s300_link_base_l">
    <visual>
      <geometry>
        <mesh filename="meshes/base.obj"/>
      </geometry>
      <material>
        <color rgba="0.1788232 0.1788232 0.1788232 1"/>
      </material>
    </visual>
    <collision>
      <geometry>
        <mesh filename="meshes/base.obj"/>
      </geometry>
    </collision>
    <inertial>
      <mass value="0.965"/>
      <origin rpy="0 0 0" xyz="0 0 0.1255"/>
      <inertia ixx="0.000951270861568" ixy="0" ixz="0" iyy="0.000951270861568" iyz="0" izz="0.000374272"/>
    </inertial>
  </link>
  <joint name="j2s7s300_joint_base_l" type="fixed">
    <parent link="torso"/>
    <child link="j2s7s300_link_base_l"/>
    <axis xyz="0 0 0"/>
    <limit effort="2000" lower="0" upper="0" velocity="1"/>
    <origin rpy="0 0 1.5707963267948966" xyz="0 0.27 0.114"/>
    <dynamics damping="0.0" friction="0.0"/>
  </joint>
  <link name="j2s7s300_link_1_l">
    <visual>
      <geometry>
        <mesh filename="meshes/shoulder.obj"/>
      </geometry>
      <material>
        <color rgba="0.1788232 0.1788232 0.1788232 1"/>
      </material>
    </visual>
    <visual>
      <geometry>
        <mesh filename="meshes/ring_big.obj"/>
      </geometry>
      <material>
        <color rgba="0.1788232 0.1788232 0.1788232 1"/>
      </material>
    </visual>
    <collision>
      <geometry>
        <mesh filename="meshes/shoulder.obj"/>
      </geometry>
    </collision>
    <inertial>
      <mass value="0.790"/>
      <origin xyz="0 -0.002 -0.0605"/>
      <inertia ixx="0.00152031725204" ixy="0" ixz="0" iyy="0.00152031725204" iyz="0" izz="0.00059816"/>
    </inertial>
  </link>
  <joint name="j2s7s300_joint_1_l" type="revolute">
    <parent link="j2s7s300_link_base_l"/>
    <child link="j2s7s300_link_1_l"/>
    <axis xyz="0 0 1"/>
    <limit effort="110" lower="0.18" upper="6.10" velocity="0.63"/>
    <origin rpy="0 3.14159265359 0" xyz="0 0 0.15675"/>
    <dynamics damping="18.0" friction="0.0"/>
  </joint>
  <transmission name="j2s7s300_joint_1_l_trans">
    <type>transmission_interface/SimpleTransmission</type>
    <joint name="j2s7s300_joint_1_l">
      <hardwareInterface>EffortJointInterface</hardwareInterface>
    </joint>
    <actuator name="j2s7s300_joint_1_l_actuator">
      <hardwareInterface>EffortJointInterface</hardwareInterface>
    </actuator>
  </transmission>
  <link name="sensor_cover_0_l">
    <visual>
      <geometry>
        <sphere radius="0.045"/>
      </geometry>
      <material>
        <color rgba="0.1788232 0.1788232 0.1788232 1"/>
      </material>
    </visual>
    <inertial>
      <mass value="0.190"/>
      <origin xyz="0 0 0"/>
      <inertia ixx="0.000154" ixy="0" ixz="0" iyy="0.000154" iyz="0" izz="0.000154"/>
    </inertial>
  </link>
  <joint name='sensor_cover_0_l_on_link_2_l' type='fixed'>
    <parent link='j2s7s300_link_2_l'/>
    <child link='sensor_cover_0_l'/>
    <origin xyz="0 -0.01 -0.05" rpy="0 0 0"/>
  </joint>
  <link name="j2s7s300_link_2_l">
    <visual>
      <geometry>
        <mesh filename="meshes/arm_half_1.obj"/>
      </geometry>
      <material>
        <color rgba="0.1788232 0.1788232 0.1788232 1"/>
      </material>
    </visual>
    <visual>
      <geometry>
        <mesh filename="meshes/ring_big.obj"/>
      </geometry>
      <material>
        <color rgba="0.1788232 0.1788232 0.1788232 1"/>
      </material>
    </visual>
    <collision>
      <geometry>
        <mesh filename="meshes/arm_half_1.obj"/>
      </geometry>
    </collision>
    <inertial>
      <mass value="0.876"/>
      <origin xyz="0 -0.106 0"/>
      <inertia ixx="0.00247073761701" ixy="0" ixz="0" iyy="0.000380115" iyz="0" izz="0.00247073761701"/>
    </inertial>
  </link>
  <joint name='j2s7s300_link_2_l_floatie_2.0a_on_link_2_l' type='fixed'>
    <parent link='j2s7s300_link_2_l'/>
    <child link='floatie_2.0a_on_link_2_l'/>
    <origin xyz="0 -0.10 0" rpy="1.507 0 0"/>
  </joint>
  <link name="floatie_2.0a_on_link_2_l">
    <!-- Add two floatie 2.0s on Left Link 2. -->
    <inertial>
      <mass value="0.065"/>
    </inertial>
    <visual name='floatie_2.0a_on_link_2_l_visual'>
      <origin xyz="0 0 0" rpy="0 0 0"/>
      <geometry>
        <cylinder length="0.055" radius="0.09"/>
      </geometry>
    </visual>
    <collision name='floatie_2.0a_on_link_2_l_collision'>
      <origin xyz="0 0 0" rpy="0 0 0"/>
      <geometry>
        <cylinder length="0.055" radius="0.09"/>
      </geometry>
      <drake:proximity_properties>
        <drake:mesh_resolution_hint value="0.04"/>
        <drake:compliant_hydroelastic/>
        <drake:hydroelastic_modulus value="1e6"/>
        <drake:hunt_crossley_dissipation value="5"/>
        <!-- Arbitrary guess at bubble friction properties -->
        <drake:mu_static value="0.8"/>
      </drake:proximity_properties>
    </collision>
  </link>
  <joint name='j2s7s300_link_2_l_floatie_2.0b_on_link_2_l' type='fixed'>
    <parent link='j2s7s300_link_2_l'/>
    <child link='floatie_2.0b_on_link_2_l'/>
    <origin xyz="0 -0.17 0" rpy="1.507 0 0"/>
  </joint>
  <link name="floatie_2.0b_on_link_2_l">
    <inertial>
      <mass value="0.065"/>
    </inertial>
    <visual name='floatie_2.0b_on_link_2_l_visual'>
      <origin xyz="0 0 0" rpy="0 0 0"/>
      <geometry>
        <cylinder length="0.055" radius="0.09"/>
      </geometry>
    </visual>
    <collision name='floatie_2.0b_on_link_2_l_collision'>
      <origin xyz="0 0 0" rpy="0 0 0"/>
      <geometry>
        <cylinder length="0.055" radius="0.09"/>
      </geometry>
      <drake:proximity_properties>
        <drake:mesh_resolution_hint value="0.04"/>
        <drake:compliant_hydroelastic/>
        <drake:hydroelastic_modulus value="1e6"/>
        <drake:hunt_crossley_dissipation value="5"/>
        <!-- Arbitrary guess at bubble friction properties -->
        <drake:mu_static value="0.8"/>
      </drake:proximity_properties>
    </collision>
  </link>
  <joint name="j2s7s300_joint_2_l" type="revolute">
    <parent link="j2s7s300_link_1_l"/>
    <child link="j2s7s300_link_2_l"/>
    <axis xyz="0 0 1"/>
    <limit effort="100" lower="0.523598775598" upper="5.75958653158" velocity="0.63"/>
    <origin rpy="-1.57079632679 0 3.14159265359" xyz="0 0.0016 -0.11875"/>
    <dynamics damping="18.0" friction="0.0"/>
  </joint>
  <transmission name="j2s7s300_joint_2_l_trans">
    <type>transmission_interface/SimpleTransmission</type>
    <joint name="j2s7s300_joint_2_l">
      <hardwareInterface>EffortJointInterface</hardwareInterface>
    </joint>
    <actuator name="j2s7s300_joint_2_l_actuator">
      <hardwareInterface>EffortJointInterface</hardwareInterface>
    </actuator>
  </transmission>
  <link name="sensor_cover_1_l">
    <visual>
      <geometry>
        <sphere radius="0.045"/>
      </geometry>
      <material>
        <color rgba="0.812 0.039 0.039 1"/>
      </material>
    </visual>
    <inertial>
      <mass value="0.190"/>
      <origin xyz="0 0 0"/>
      <inertia ixx="0.000154" ixy="0" ixz="0" iyy="0.000154" iyz="0" izz="0.000154"/>
    </inertial>
  </link>
  <joint name='sensor_cover_1_l_on_link_3_l' type='fixed'>
    <parent link='j2s7s300_link_3_l'/>
    <child link='sensor_cover_1_l'/>
    <origin xyz="0 0.055 -0.195" rpy="0 0 0"/>
  </joint>
  <link name="j2s7s300_link_3_l">
    <visual>
      <geometry>
        <cylinder length="0.31" radius="0.085"/>
      </geometry>
      <material>
        <color rgba="0.812 0.039 0.039 1"/>
      </material>
    </visual>

    <visual>
      <geometry>
        <mesh filename="meshes/arm_half_2.obj"/>
      </geometry>
      <material>
        <color rgba="0.812 0.039 0.039 1"/>
      </material>
    </visual>
    <visual>
      <geometry>
        <mesh filename="meshes/ring_big.obj"/>
      </geometry>
      <material>
        <color rgba="0.627451 0.627451 0.627451 1"/>
      </material>
    </visual>
    <collision>
      <geometry>
        <mesh filename="meshes/arm_half_2.obj"/>
      </geometry>
    </collision>
    <inertial>
      <mass value="0.876"/>
      <origin xyz="0 0 -0.106"/>
      <inertia ixx="0.00247073761701" ixy="0" ixz="0" iyy="0.00247073761701" iyz="0" izz="0.000380115"/>
    </inertial>
  </link>
  <joint name='j2s7s300_link_3_l_floatie_2.0a_on_link_3_l' type='fixed'>
    <parent link='j2s7s300_link_3_l'/>
    <child link='floatie_2.0a_on_link_3_l'/>
    <origin xyz="0 0 -0.049" rpy="0 0 0"/>
  </joint>
  <link name="floatie_2.0a_on_link_3_l">
    <!-- Add two floatie 2.0s on Left Link 3. -->
    <inertial>
      <mass value="0.065"/>
    </inertial>
    <visual name='floatie_2.0a_on_link_3_l_visual'>
      <origin xyz="0 0 0" rpy="0 0 0"/>
      <geometry>
        <cylinder length="0.055" radius="0.09"/>
      </geometry>
    </visual>
    <collision name='floatie_2.0a_on_link_3_l_collision'>
      <origin xyz="0 0 0" rpy="0 0 0"/>
      <geometry>
        <cylinder length="0.055" radius="0.09"/>
      </geometry>
      <drake:proximity_properties>
        <drake:mesh_resolution_hint value="0.04"/>
        <drake:compliant_hydroelastic/>
        <drake:hydroelastic_modulus value="1e6"/>
        <drake:hunt_crossley_dissipation value="5"/>
        <!-- Arbitrary guess at bubble friction properties -->
        <drake:mu_static value="0.8"/>
      </drake:proximity_properties>
    </collision>
  </link>
  <joint name='j2s7s300_link_3_l_floatie_2.0b_on_link_3_l' type='fixed'>
    <parent link='j2s7s300_link_3_l'/>
    <child link='floatie_2.0b_on_link_3_l'/>
    <origin xyz="0 0 -0.11" rpy="0 0 0"/>
  </joint>
  <link name="floatie_2.0b_on_link_3_l">
    <inertial>
      <mass value="0.065"/>
    </inertial>
    <visual name='floatie_2.0b_on_link_3_l_visual'>
      <origin xyz="0 0 0" rpy="0 0 0"/>
      <geometry>
        <cylinder length="0.055" radius="0.09"/>
      </geometry>
    </visual>
    <collision name='floatie_2.0b_on_link_3_l_collision'>
      <origin xyz="0 0 0" rpy="0 0 0"/>
      <geometry>
        <cylinder length="0.055" radius="0.09"/>
      </geometry>
      <drake:proximity_properties>
        <drake:mesh_resolution_hint value="0.04"/>
        <drake:compliant_hydroelastic/>
        <drake:hydroelastic_modulus value="1e6"/>
        <drake:hunt_crossley_dissipation value="5"/>
        <!-- Arbitrary guess at bubble friction properties -->
        <drake:mu_static value="0.8"/>
      </drake:proximity_properties>
    </collision>
  </link>
  <joint name="j2s7s300_joint_3_l" type="revolute">
    <parent link="j2s7s300_link_2_l"/>
    <child link="j2s7s300_link_3_l"/>
    <axis xyz="0 0 1"/>
    <limit effort="100" lower="0.18" upper="6.10" velocity="0.63"/>
    <origin rpy="-1.57079632679 0 0" xyz="0 -0.205 0"/>
    <dynamics damping="18.0" friction="0.0"/>
  </joint>
  <transmission name="j2s7s300_joint_3_l_trans">
    <type>transmission_interface/SimpleTransmission</type>
    <joint name="j2s7s300_joint_3_l">
      <hardwareInterface>EffortJointInterface</hardwareInterface>
    </joint>
    <actuator name="j2s7s300_joint_3_l_actuator">
      <hardwareInterface>EffortJointInterface</hardwareInterface>
    </actuator>
  </transmission>
  <link name="sensor_cover_2_l">
    <visual>
      <geometry>
        <sphere radius="0.045"/>
      </geometry>
      <material>
        <color rgba="0.812 0.039 0.039 1"/>
      </material>
    </visual>
    <inertial>
      <mass value="0.190"/>
      <origin xyz="0 0 0"/>
      <inertia ixx="0.000154" ixy="0" ixz="0" iyy="0.000154" iyz="0" izz="0.000154"/>
    </inertial>
  </link>
  <joint name='sensor_cover_2_l_on_link_4_l' type='fixed'>
    <parent link='j2s7s300_link_4_l'/>
    <child link='sensor_cover_2_l'/>
    <origin xyz="0 0.01 -0.05" rpy="0 0 0"/>
  </joint>
  <link name="j2s7s300_link_4_l">
    <visual>
      <geometry>
        <mesh filename="meshes/forearm.obj"/>
      </geometry>
      <material>
        <color rgba="0.812 0.039 0.039 1"/>
      </material>
    </visual>
    <visual>
      <geometry>
        <mesh filename="meshes/ring_small.obj"/>
      </geometry>
      <material>
        <color rgba="0.627451 0.627451 0.627451 1"/>
      </material>
    </visual>
    <collision>
      <geometry>
        <mesh filename="meshes/forearm.obj"/>
      </geometry>
    </collision>
    <inertial>
      <mass value="0.625"/>
      <origin xyz="0 0.119 -0.0086"/>
      <inertia ixx="0.00142022431908" ixy="0" ixz="0" iyy="0.000304335" iyz="0" izz="0.00142022431908"/>
    </inertial>
  </link>
  <joint name='j2s7s300_link_4_l_floatie_2.0a_on_link_4_l' type='fixed'>
    <parent link='j2s7s300_link_4_l'/>
    <child link='floatie_2.0a_on_link_4_l'/>
    <origin xyz="0 0.085 -0.01" rpy="1.6 0 0"/>
  </joint>
  <link name="floatie_2.0a_on_link_4_l">
    <!-- Add two floatie 2.0s on Left Link 4. -->
    <inertial>
      <mass value="0.065"/>
    </inertial>
    <visual name='floatie_2.0a_on_link_4_l_visual'>
      <origin xyz="0 0 0" rpy="0 0 0"/>
      <geometry>
        <cylinder length="0.055" radius="0.09"/>
      </geometry>
    </visual>
    <collision name='floatie_2.0a_on_link_4_l_collision'>
      <origin xyz="0 0 0" rpy="0 0 0"/>
      <geometry>
        <cylinder length="0.055" radius="0.09"/>
      </geometry>
      <drake:proximity_properties>
        <drake:mesh_resolution_hint value="0.04"/>
        <drake:compliant_hydroelastic/>
        <drake:hydroelastic_modulus value="1e6"/>
        <drake:hunt_crossley_dissipation value="5"/>
        <!-- Arbitrary guess at bubble friction properties -->
        <drake:mu_static value="0.8"/>
      </drake:proximity_properties>
    </collision>
  </link>
  <joint name='j2s7s300_link_4_l_floatie_2.0b_on_link_4_l' type='fixed'>
    <parent link='j2s7s300_link_4_l'/>
    <child link='floatie_2.0b_on_link_4_l'/>
    <origin xyz="0 0.16 -0.01" rpy="1.6 0 0"/>
  </joint>
  <link name="floatie_2.0b_on_link_4_l">
    <inertial>
      <mass value="0.065"/>
    </inertial>
    <visual name='floatie_2.0b_on_link_4_l_visual'>
      <origin xyz="0 0 0" rpy="0 0 0"/>
      <geometry>
        <cylinder length="0.055" radius="0.09"/>
      </geometry>
    </visual>
    <collision name='floatie_2.0b_on_link_4_l_collision'>
      <origin xyz="0 0 0" rpy="0 0 0"/>
      <geometry>
        <cylinder length="0.055" radius="0.09"/>
      </geometry>
      <drake:proximity_properties>
        <drake:mesh_resolution_hint value="0.04"/>
        <drake:compliant_hydroelastic/>
        <drake:hydroelastic_modulus value="1e6"/>
        <drake:hunt_crossley_dissipation value="5"/>
        <!-- Arbitrary guess at bubble friction properties -->
        <drake:mu_static value="0.8"/>
      </drake:proximity_properties>
    </collision>
  </link>
  <joint name="j2s7s300_joint_4_l" type="revolute">
    <parent link="j2s7s300_link_3_l"/>
    <child link="j2s7s300_link_4_l"/>
    <axis xyz="0 0 1"/>
    <limit effort="100" lower="0.523598775598" upper="5.75958653158" velocity="0.63"/>
    <origin rpy="1.57079632679 0 3.14159265359" xyz="0 0 -0.205"/>
    <dynamics damping="18.0" friction="0.0"/>
  </joint>
  <transmission name="j2s7s300_joint_4_l_trans">
    <type>transmission_interface/SimpleTransmission</type>
    <joint name="j2s7s300_joint_4_l">
      <hardwareInterface>EffortJointInterface</hardwareInterface>
    </joint>
    <actuator name="j2s7s300_joint_4_l_actuator">
      <hardwareInterface>EffortJointInterface</hardwareInterface>
    </actuator>
  </transmission>
  <link name="j2s7s300_link_5_l">
    <visual>
      <origin xyz="0 0 0.075"/>
      <geometry>
        <cylinder length="0.18" radius="0.085"/>
      </geometry>
      <material>
        <color rgba="0.812 0.039 0.039 1"/>
      </material>
    </visual>
    <visual>
      <geometry>
        <mesh filename="meshes/wrist_spherical_1.obj"/>
      </geometry>
      <material>
        <color rgba="0.812 0.039 0.039 1"/>
      </material>
    </visual>
    <visual>
      <geometry>
        <mesh filename="meshes/ring_small.obj"/>
      </geometry>
      <material>
        <color rgba="0.627451 0.627451 0.627451 1"/>
      </material>
    </visual>
    <collision>
      <geometry>
        <mesh filename="meshes/wrist_spherical_1.obj"/>
      </geometry>
    </collision>
    <inertial>
      <mass value="0.485"/>
      <origin xyz="0 0.0028848942 -0.063"/>
      <inertia ixx="0.0004321316048" ixy="0" ixz="0" iyy="0.0004321316048" iyz="0" izz="9.26e-05"/>
    </inertial>
  </link>
  <joint name="j2s7s300_joint_5_l" type="revolute">
    <parent link="j2s7s300_link_4_l"/>
    <child link="j2s7s300_link_5_l"/>
    <axis xyz="0 0 1"/>
    <limit effort="80" lower="0.18" upper="6.10" velocity="0.85"/>
    <origin rpy="-1.57079632679 0 3.14159265359" xyz="0 0.2073 -0.0114"/>
    <dynamics damping="3.0" friction="0.0"/>
  </joint>
  <transmission name="j2s7s300_joint_5_l_trans">
    <type>transmission_interface/SimpleTransmission</type>
    <joint name="j2s7s300_joint_5_l">
      <hardwareInterface>EffortJointInterface</hardwareInterface>
    </joint>
    <actuator name="j2s7s300_joint_5_l_actuator">
      <hardwareInterface>EffortJointInterface</hardwareInterface>
    </actuator>
  </transmission>
  <link name="j2s7s300_link_6_l">
    <visual>
      <geometry>
        <mesh filename="meshes/wrist_spherical_2.obj"/>
      </geometry>
      <material>
        <color rgba="0.812 0.039 0.039 1"/>
      </material>
    </visual>
    <visual>
      <geometry>
        <mesh filename="meshes/ring_small.obj"/>
      </geometry>
      <material>
        <color rgba="0.627451 0.627451 0.627451 1"/>
      </material>
    </visual>
    <collision>
      <geometry>
        <mesh filename="meshes/wrist_spherical_2.obj"/>
      </geometry>
    </collision>
    <inertial>
      <mass value="0.486"/>
      <origin xyz="0 0.063 -0.0028562765"/>
      <inertia ixx="0.0004321316048" ixy="0" ixz="0" iyy="9.26e-05" iyz="0" izz="0.0004321316048"/>
    </inertial>
  </link>
  <joint name="j2s7s300_joint_floatie_1.0_partA_l" type="fixed">
    <parent link="j2s7s300_link_6_l"/>
    <child link="floatie_1.0_on_link_6_l"/>
    <origin rpy="1.55 0 0" xyz="0 0.055 0.005"/>
  </joint>
  <link name="floatie_1.0_on_link_6_l">
    <inertial>
      <mass value="0.025"/>
    </inertial>
    <visual name='floatie_1.0_on_link_6_l_visual_1'>
      <origin rpy="0 0 0" xyz="0 0 0"/>
      <geometry>
        <cylinder length="0.045" radius="0.0775"/>
      </geometry>
      <material>
        <color rgba="0.812 0.039 0.039 1"/>
      </material>
    </visual>
    <collision name='floatie_1.0_on_link_6_l_collision_1'>
      <origin rpy="0 0 0" xyz="0 0 0"/>
      <geometry>
        <cylinder length="0.045" radius="0.0775"/>
      </geometry>
      <drake:proximity_properties>
        <drake:mesh_resolution_hint value="0.04"/>
        <drake:compliant_hydroelastic/>
        <drake:hydroelastic_modulus value="1e6"/>
        <drake:hunt_crossley_dissipation value="5"/>
        <!-- Arbitrary guess at bubble friction properties -->
        <drake:mu_static value="0.8"/>
      </drake:proximity_properties>
    </collision>
    <visual name='floatie_1.0_on_link_6_l_visual_2'>
      <origin rpy="0 0 0" xyz="0 0 0.06"/>
      <geometry>
        <sphere radius="0.0775"/>
      </geometry>
    </visual>
    <collision name='floatie_1.0_on_link_6_l_collision_2'>
      <origin rpy="0 0 0" xyz="0 0 0.045"/>
      <geometry>
        <sphere radius="0.0775"/>
      </geometry>
      <drake:proximity_properties>
        <drake:mesh_resolution_hint value="0.04"/>
        <drake:compliant_hydroelastic/>
        <drake:hydroelastic_modulus value="1e6"/>
        <drake:hunt_crossley_dissipation value="5"/>
        <!-- Arbitrary guess at bubble friction properties -->
        <drake:mu_static value="0.8"/>
      </drake:proximity_properties>
    </collision>
  </link>
  <joint name="j2s7s300_joint_floatie_1.0_partB_l" type="fixed">
    <parent link="j2s7s300_link_5_l"/>
    <child link="floatie_1.0_on_link_5_l"/>
    <origin rpy="0 0 0" xyz="0 0.005 -0.04"/>
  </joint>
 <link name="floatie_1.0_on_link_5_l">
    <inertial>
      <mass value="0.025"/>
    </inertial>
    <visual name='floatie_1.0_on_link_5_l_visual'>
      <origin rpy="0 0 0" xyz="0 0 0"/>
      <geometry>
        <cylinder length="0.045" radius="0.0775"/>
      </geometry>
      <material>
        <color rgba="0.812 0.039 0.039 1"/>
      </material>
    </visual>
    <collision name='floatie_1.0_on_link_5_l_collision'>
      <origin rpy="0 0 0" xyz="0 0 0"/>
      <geometry>
        <cylinder length="0.045" radius="0.0775"/>
      </geometry>
      <drake:proximity_properties>
        <drake:mesh_resolution_hint value="0.04"/>
        <drake:compliant_hydroelastic/>
        <drake:hydroelastic_modulus value="1e6"/>
        <drake:hunt_crossley_dissipation value="5"/>
        <!-- Arbitrary guess at bubble friction properties -->
        <drake:mu_static value="0.8"/>
      </drake:proximity_properties>
    </collision>
  </link>
  <joint name="j2s7s300_joint_6_l" type="revolute">
    <parent link="j2s7s300_link_5_l"/>
    <child link="j2s7s300_link_6_l"/>
    <axis xyz="0 0 1"/>
    <limit effort="80" lower="0.523598775598" upper="5.75958653158" velocity="0.85"/>
    <origin rpy="1.57079632679 0 3.14159265359" xyz="0 0 -0.10375"/>
    <dynamics damping="3.0" friction="0.0"/>
  </joint>
  <transmission name="j2s7s300_joint_6_l_trans">
    <type>transmission_interface/SimpleTransmission</type>
    <joint name="j2s7s300_joint_6_l">
      <hardwareInterface>EffortJointInterface</hardwareInterface>
    </joint>
    <actuator name="j2s7s300_joint_6_l_actuator">
      <hardwareInterface>EffortJointInterface</hardwareInterface>
    </actuator>
  </transmission>
  <link name="j2s7s300_link_7_l">
    <inertial>
      <mass value="0.01"/>
      <origin xyz="0 0 0"/>
      <inertia ixx="0.00001" ixy="0" ixz="0" iyy="0.00001" iyz="0" izz="0.00001"/>
    </inertial>
  </link>
  <joint name="j2s7s300_joint_7_l" type="revolute">
    <parent link="j2s7s300_link_6_l"/>
    <child link="j2s7s300_link_7_l"/>
    <axis xyz="0 0 1"/>
    <limit effort="80" lower="0.18" upper="6.10" velocity="0.85"/>
    <origin rpy="-1.57079632679 0 3.14159265359" xyz="0 0.10375 0"/>
    <dynamics damping="3.0" friction="0.0"/>
  </joint>
  <transmission name="j2s7s300_joint_7_l_trans">
    <type>transmission_interface/SimpleTransmission</type>
    <joint name="j2s7s300_joint_7_l">
      <hardwareInterface>EffortJointInterface</hardwareInterface>
    </joint>
    <actuator name="j2s7s300_joint_7_l_actuator">
      <hardwareInterface>EffortJointInterface</hardwareInterface>
    </actuator>
  </transmission>
  <link name="paw_link_l">
    <!-- Add the paw mount only for visual. -->
    <visual>
      <geometry>
        <mesh filename="meshes/MA-027-AY-0006_mount.obj"/>
      </geometry>
      <material>
        <color rgba="0.1788232 0.1788232 0.1788232 1"/>
      </material>
    </visual>
    <!-- Add the paw frame for visual and collision. -->
    <visual>
      <geometry>
        <mesh filename="meshes/MA-027-AY-0006_pawframe.obj"/>
      </geometry>
      <material>
        <color rgba="0.1788232 0.1788232 0.1788232 1"/>
      </material>
    </visual>
    <collision>
      <origin xyz="-0.03 0.06 0" rpy="1.57 0 0.9"/>
      <geometry>
        <cylinder length="0.055" radius="0.025"/>
      </geometry>
    </collision>
    <collision>
      <geometry>
        <mesh filename="meshes/MA-027-AY-0006_bubble35mm_coarse_250faces.vtk"/>
      </geometry>
      <drake:proximity_properties>
        <drake:mesh_resolution_hint value="0.04"/>
        <drake:compliant_hydroelastic/>
        <drake:hydroelastic_modulus value="1e6"/>
        <drake:hunt_crossley_dissipation value="5"/>
        <!-- Arbitrary guess at bubble friction properties -->
        <drake:mu_static value="0.9"/>
        <drake:mu_dynamic value="0.9"/>
      </drake:proximity_properties>
    </collision>
    <!-- Add the bubble mesh for visual and collision. -->
    <visual>
      <geometry>
        <mesh filename="meshes/MA-027-AY-0006_bubble35mm.obj"/>
      </geometry>
    </visual>
    <!-- Inertial values are approximate and calculated for a
         cylinder of radius 35mm, height 110mm and mass 270gms -->
    <inertial>
      <mass value="0.27"/>
      <origin xyz="-0.05 0.07 0" rpy="1.5707 0 0.85"/>
      <inertia ixx="0.000355" ixy="0" ixz="0" iyy="0.000355" iyz="0" izz="0.000165"/>
    </inertial>
  </link>
  <joint name='paw_joint_l' type='fixed'>
    <parent link='j2s7s300_link_7_l'/>
    <child link='paw_link_l'/>
    <origin rpy="-1.5705 0 2.0944" xyz="0 0 0"/>
  </joint>
  <link name="bubble_center_l">
    <inertial>
      <mass value="0.001"/>
      <origin xyz="0 0 0"/>
      <inertia ixx="0.000001" ixy="0" ixz="0" iyy="0.000001" iyz="0" izz="0.000001"/>
    </inertial>
  </link>
  <joint name='dummy_joint_l' type='fixed'>
    <parent link='paw_link_l'/>
    <child link='bubble_center_l'/>
    <origin rpy="0 0 0" xyz="-0.1295 0.0831 0.0017"/>
  </joint>

  <link name="j2s7s300_link_base_r">
    <visual>
      <geometry>
        <mesh filename="meshes/base.obj"/>
      </geometry>
      <material>
        <color rgba="0.1788232 0.1788232 0.1788232 1"/>
      </material>
    </visual>
    <collision>
      <geometry>
        <mesh filename="meshes/base.obj"/>
      </geometry>
    </collision>
    <inertial>
      <mass value="0.965"/>
      <origin rpy="0 0 0" xyz="0.0 0.0 0.1255"/>
      <inertia ixx="0.000951270861568" ixy="0" ixz="0" iyy="0.000951270861568" iyz="0" izz="0.000374272"/>
    </inertial>
  </link>

  <joint name="j2s7s300_joint_base_r" type="fixed">
    <parent link="torso"/>
    <child link="j2s7s300_link_base_r"/>
    <axis xyz="0 0 0"/>
    <limit effort="2000" lower="0" upper="0" velocity="1"/>
    <origin rpy="0 0 1.5707963267948966" xyz="0 -0.27 0.114"/>
    <dynamics damping="0.0" friction="0.0"/>
  </joint>
  <link name="j2s7s300_link_1_r">
    <visual>
      <geometry>
        <mesh filename="meshes/shoulder.obj"/>
      </geometry>
      <material>
        <color rgba="0.1788232 0.1788232 0.1788232 1"/>
      </material>
    </visual>
    <visual>
      <geometry>
        <mesh filename="meshes/ring_big.obj"/>
      </geometry>
      <material>
        <color rgba="0.1788232 0.1788232 0.1788232 1"/>
      </material>
    </visual>
    <collision>
      <geometry>
        <mesh filename="meshes/shoulder.obj"/>
      </geometry>
    </collision>
    <inertial>
      <mass value="0.790"/>
      <origin xyz="0 -0.002 -0.0605"/>
      <inertia ixx="0.00152031725204" ixy="0" ixz="0" iyy="0.00152031725204" iyz="0" izz="0.00059816"/>
    </inertial>
  </link>
  <joint name="j2s7s300_joint_1_r" type="revolute">
    <parent link="j2s7s300_link_base_r"/>
    <child link="j2s7s300_link_1_r"/>
    <axis xyz="0 0 1"/>
    <limit effort="110" lower="0.18" upper="6.10" velocity="0.63"/>
    <origin rpy="0 3.14159265359 0" xyz="0 0 0.15675"/>
    <dynamics damping="18.0" friction="0.0"/>
  </joint>
  <transmission name="j2s7s300_joint_1_r_trans">
    <type>transmission_interface/SimpleTransmission</type>
    <joint name="j2s7s300_joint_1_r">
      <hardwareInterface>EffortJointInterface</hardwareInterface>
    </joint>
    <actuator name="j2s7s300_joint_1_r_actuator">
      <hardwareInterface>EffortJointInterface</hardwareInterface>
    </actuator>
  </transmission>
  <link name="sensor_cover_0_r">
    <visual>
      <geometry>
        <sphere radius="0.045"/>
      </geometry>
      <material>
        <color rgba="0.1788232 0.1788232 0.1788232 1"/>
      </material>
    </visual>
    <inertial>
      <mass value="0.190"/>
      <origin xyz="0 0 0"/>
      <inertia ixx="0.000154" ixy="0" ixz="0" iyy="0.000154" iyz="0" izz="0.000154"/>
    </inertial>
  </link>
  <joint name='sensor_cover_0_r_on_link_2_r' type='fixed'>
    <parent link='j2s7s300_link_2_r'/>
    <child link='sensor_cover_0_r'/>
    <origin xyz="0 -0.01 -0.05" rpy="0 0 0"/>
  </joint>
  <link name="j2s7s300_link_2_r">
    <visual>
      <geometry>
        <mesh filename="meshes/arm_half_1.obj"/>
      </geometry>
      <material>
        <color rgba="0.1788232 0.1788232 0.1788232 1"/>
      </material>
    </visual>
    <visual>
      <geometry>
        <mesh filename="meshes/ring_big.obj"/>
      </geometry>
      <material>
        <color rgba="0.1788232 0.1788232 0.1788232 1"/>
      </material>
    </visual>
    <collision>
      <geometry>
        <mesh filename="meshes/arm_half_1.obj"/>
      </geometry>
    </collision>
    <inertial>
      <mass value="0.876"/>
      <origin xyz="0 -0.106 0"/>
      <inertia ixx="0.00247073761701" ixy="0" ixz="0" iyy="0.000380115" iyz="0" izz="0.00247073761701"/>
    </inertial>
  </link>
  <joint name='j2s7s300_link_2_r_floatie_2.0a_on_link_2_r' type='fixed'>
    <parent link='j2s7s300_link_2_r'/>
    <child link='floatie_2.0a_on_link_2_r'/>
    <origin xyz="0 -0.10 0" rpy="1.507 0 0"/>
  </joint>
  <link name='floatie_2.0a_on_link_2_r'>
    <!-- Add two floatie 2.0s on Right Link 2. -->
    <inertial>
      <mass value="0.065"/>
    </inertial>
    <visual name='floatie_2.0a_on_link_2_r_visual'>
      <origin xyz="0 0 0" rpy="0 0 0"/>
      <geometry>
        <cylinder length="0.055" radius="0.09"/>
      </geometry>
    </visual>
    <collision name='floatie_2.0a_on_link_2_r_collision'>
      <origin xyz="0 0 0" rpy="0 0 0"/>
      <geometry>
        <cylinder length="0.055" radius="0.09"/>
      </geometry>
      <drake:proximity_properties>
        <drake:mesh_resolution_hint value="0.04"/>
        <drake:compliant_hydroelastic/>
        <drake:hydroelastic_modulus value="1e6"/>
        <drake:hunt_crossley_dissipation value="5"/>
        <!-- Arbitrary guess at bubble friction properties -->
        <drake:mu_static value="0.8"/>
      </drake:proximity_properties>
    </collision>
  </link>
  <joint name='j2s7s300_link_2_r_floatie_2.0b_on_link_2_r' type='fixed'>
    <parent link='j2s7s300_link_2_r'/>
    <child link='floatie_2.0b_on_link_2_r'/>
    <origin xyz="0 -0.17 0" rpy="1.507 0 0"/>
  </joint>
  <link name='floatie_2.0b_on_link_2_r'>
    <inertial>
      <mass value="0.065"/>
    </inertial>
    <visual name='floatie_2.0b_on_link_2_r_visual'>
      <origin xyz="0 0 0" rpy="0 0 0"/>
      <geometry>
        <cylinder length="0.055" radius="0.09"/>
      </geometry>
    </visual>
    <collision name='floatie_2.0b_on_link_2_r_collision'>
      <origin xyz="0 0 0" rpy="0 0 0"/>
      <geometry>
        <cylinder length="0.055" radius="0.09"/>
      </geometry>
      <drake:proximity_properties>
        <drake:mesh_resolution_hint value="0.04"/>
        <drake:compliant_hydroelastic/>
        <drake:hydroelastic_modulus value="1e6"/>
        <drake:hunt_crossley_dissipation value="5"/>
        <!-- Arbitrary guess at bubble friction properties -->
        <drake:mu_static value="0.8"/>
      </drake:proximity_properties>
    </collision>
  </link>
  <joint name="j2s7s300_joint_2_r" type="revolute">
    <parent link="j2s7s300_link_1_r"/>
    <child link="j2s7s300_link_2_r"/>
    <axis xyz="0 0 1"/>
    <limit effort="100" lower="0.523598775598" upper="5.75958653158" velocity="0.63"/>
    <origin rpy="-1.57079632679 0 3.14159265359" xyz="0 0.0016 -0.11875"/>
    <dynamics damping="18.0" friction="0.0"/>
  </joint>
  <transmission name="j2s7s300_joint_2_r_trans">
    <type>transmission_interface/SimpleTransmission</type>
    <joint name="j2s7s300_joint_2_r">
      <hardwareInterface>EffortJointInterface</hardwareInterface>
    </joint>
    <actuator name="j2s7s300_joint_2_r_actuator">
      <hardwareInterface>EffortJointInterface</hardwareInterface>
    </actuator>
  </transmission>
  <link name="sensor_cover_1_r">
    <visual>
      <geometry>
        <sphere radius="0.045"/>
      </geometry>
      <material>
        <color rgba="0.812 0.039 0.039 1"/>
      </material>
    </visual>
    <inertial>
      <mass value="0.190"/>
      <origin xyz="0 0 0"/>
      <inertia ixx="0.000154" ixy="0" ixz="0" iyy="0.000154" iyz="0" izz="0.000154"/>
    </inertial>
  </link>
  <joint name='sensor_cover_1_r_on_link_3_r' type='fixed'>
    <parent link='j2s7s300_link_3_r'/>
    <child link='sensor_cover_1_r'/>
    <origin xyz="0 0.055 -0.195" rpy="0 0 0"/>
  </joint>
  <link name="j2s7s300_link_3_r">
    <visual>
      <geometry>
        <cylinder length="0.31" radius="0.085"/>
      </geometry>
      <material>
        <color rgba="0.812 0.039 0.039 1"/>
      </material>
    </visual>
    <visual>
      <geometry>
        <mesh filename="meshes/arm_half_2.obj"/>
      </geometry>
      <material>
        <color rgba="0.812 0.039 0.039 1"/>
      </material>
    </visual>
    <visual>
      <geometry>
        <mesh filename="meshes/ring_big.obj"/>
      </geometry>
      <material>
        <color rgba="0.627451 0.627451 0.627451 1"/>
      </material>
    </visual>
    <collision>
      <geometry>
        <mesh filename="meshes/arm_half_2.obj"/>
      </geometry>
    </collision>
    <inertial>
      <mass value="0.876"/>
      <origin xyz="0 0 -0.106"/>
      <inertia ixx="0.00247073761701" ixy="0" ixz="0" iyy="0.00247073761701" iyz="0" izz="0.000380115"/>
    </inertial>
  </link>
  <joint name='j2s7s300_link_3_r_floatie_2.0a_on_link_3_r' type='fixed'>
    <parent link='j2s7s300_link_3_r'/>
    <child link='floatie_2.0a_on_link_3_r'/>
    <origin xyz="0 0 -0.049" rpy="0 0 0"/>
  </joint>
  <link name='floatie_2.0a_on_link_3_r'>
    <!-- Add two floatie 2.0s on Right Link 3. -->
    <inertial>
      <mass value="0.065"/>
    </inertial>
    <visual name='floatie_2.0a_on_link_3_r_visual'>
      <origin xyz="0 0 0" rpy="0 0 0"/>
      <geometry>
        <cylinder length="0.055" radius="0.09"/>
      </geometry>
    </visual>
    <collision name='floatie_2.0a_on_link_3_r_collision'>
      <origin xyz="0 0 0" rpy="0 0 0"/>
      <geometry>
        <cylinder length="0.055" radius="0.09"/>
      </geometry>
      <drake:proximity_properties>
        <drake:mesh_resolution_hint value="0.04"/>
        <drake:compliant_hydroelastic/>
        <drake:hydroelastic_modulus value="1e6"/>
        <drake:hunt_crossley_dissipation value="5"/>
        <!-- Arbitrary guess at bubble friction properties -->
        <drake:mu_static value="0.8"/>
      </drake:proximity_properties>
    </collision>
  </link>
  <joint name='j2s7s300_link_3_r_floatie_2.0b_on_link_3_r' type='fixed'>
    <parent link='j2s7s300_link_3_r'/>
    <child link='floatie_2.0b_on_link_3_r'/>
    <origin xyz="0 0 -0.11" rpy="0 0 0"/>
  </joint>
  <link name='floatie_2.0b_on_link_3_r'>
    <inertial>
      <mass value="0.065"/>
    </inertial>
    <visual name='floatie_2.0b_on_link_3_r_visual'>
      <origin xyz="0 0 0" rpy="0 0 0"/>
      <geometry>
        <cylinder length="0.055" radius="0.09"/>
      </geometry>
    </visual>
    <collision name='floatie_2.0b_on_link_3_r_collision'>
      <origin xyz="0 0 0" rpy="0 0 0"/>
      <geometry>
        <cylinder length="0.055" radius="0.09"/>
      </geometry>
      <drake:proximity_properties>
        <drake:mesh_resolution_hint value="0.04"/>
        <drake:compliant_hydroelastic/>
        <drake:hydroelastic_modulus value="1e6"/>
        <drake:hunt_crossley_dissipation value="5"/>
        <!-- Arbitrary guess at bubble friction properties -->
        <drake:mu_static value="0.8"/>
      </drake:proximity_properties>
    </collision>
  </link>
  <joint name="j2s7s300_joint_3_r" type="revolute">
    <parent link="j2s7s300_link_2_r"/>
    <child link="j2s7s300_link_3_r"/>
    <axis xyz="0 0 1"/>
    <limit effort="100" lower="0.18" upper="6.10" velocity="0.63"/>
    <origin rpy="-1.57079632679 0 0" xyz="0 -0.205 0"/>
    <dynamics damping="18.0" friction="0.0"/>
  </joint>
  <transmission name="j2s7s300_joint_3_r_trans">
    <type>transmission_interface/SimpleTransmission</type>
    <joint name="j2s7s300_joint_3_r">
      <hardwareInterface>EffortJointInterface</hardwareInterface>
    </joint>
    <actuator name="j2s7s300_joint_3_r_actuator">
      <hardwareInterface>EffortJointInterface</hardwareInterface>
    </actuator>
  </transmission>
  <link name="sensor_cover_2_r">
    <visual>
      <geometry>
        <sphere radius="0.045"/>
      </geometry>
      <material>
        <color rgba="0.812 0.039 0.039 1"/>
      </material>
    </visual>
    <inertial>
      <mass value="0.190"/>
      <origin xyz="0 0 0"/>
      <inertia ixx="0.000154" ixy="0" ixz="0" iyy="0.000154" iyz="0" izz="0.000154"/>
    </inertial>
  </link>
  <joint name='sensor_cover_2_r_on_link_4_r' type='fixed'>
    <parent link='j2s7s300_link_4_r'/>
    <child link='sensor_cover_2_r'/>
    <origin xyz="0 0.01 -0.05" rpy="0 0 0"/>
  </joint>
  <link name="j2s7s300_link_4_r">
    <visual>
      <geometry>
        <mesh filename="meshes/forearm.obj"/>
      </geometry>
      <material>
        <color rgba="0.812 0.039 0.039 1"/>
      </material>
    </visual>
    <visual>
      <geometry>
        <mesh filename="meshes/ring_small.obj"/>
      </geometry>
      <material>
        <color rgba="0.627451 0.627451 0.627451 1"/>
      </material>
    </visual>
    <collision>
      <geometry>
        <mesh filename="meshes/forearm.obj"/>
      </geometry>
    </collision>
    <inertial>
      <mass value="0.625"/>
      <origin xyz="0 0.119 -0.0086"/>
      <inertia ixx="0.00142022431908" ixy="0" ixz="0" iyy="0.000304335" iyz="0" izz="0.00142022431908"/>
    </inertial>
  </link>
  <joint name='j2s7s300_link_4_r_floatie_2.0a_on_link_4_r' type='fixed'>
    <parent link='j2s7s300_link_4_r'/>
    <child link='floatie_2.0a_on_link_4_r'/>
    <origin xyz="0 0.085 -0.01" rpy="1.6 0 0"/>
  </joint>
  <link name='floatie_2.0a_on_link_4_r'>
    <!-- Add two floatie 2.0s on Right Link 4. -->
    <inertial>
      <mass value="0.065"/>
    </inertial>
    <visual name='floatie_2.0a_on_link_4_r_visual'>
      <origin xyz="0 0 0" rpy="0 0 0"/>
      <geometry>
        <cylinder length="0.055" radius="0.09"/>
      </geometry>
    </visual>
    <collision name='floatie_2.0a_on_link_4_r_collision'>
      <origin xyz="0 0 0" rpy="0 0 0"/>
      <geometry>
        <cylinder length="0.055" radius="0.09"/>
      </geometry>
      <drake:proximity_properties>
        <drake:mesh_resolution_hint value="0.04"/>
        <drake:compliant_hydroelastic/>
        <drake:hydroelastic_modulus value="1e6"/>
        <drake:hunt_crossley_dissipation value="5"/>
        <!-- Arbitrary guess at bubble friction properties -->
        <drake:mu_static value="0.8"/>
      </drake:proximity_properties>
    </collision>
  </link>
  <joint name='j2s7s300_link_4_r_floatie_2.0b_on_link_4_r' type='fixed'>
    <parent link='j2s7s300_link_4_r'/>
    <child link='floatie_2.0b_on_link_4_r'/>
    <origin xyz="0 0.16 -0.01" rpy="1.6 0 0"/>
  </joint>
  <link name='floatie_2.0b_on_link_4_r'>
    <inertial>
      <mass value="0.065"/>
    </inertial>
    <visual name='floatie_2.0b_on_link_4_r_visual'>
      <origin xyz="0 0 0" rpy="0 0 0"/>
      <geometry>
        <cylinder length="0.055" radius="0.09"/>
      </geometry>
    </visual>
    <collision name='floatie_2.0b_on_link_4_r_collision'>
      <origin xyz="0 0 0" rpy="0 0 0"/>
      <geometry>
        <cylinder length="0.055" radius="0.09"/>
      </geometry>
      <drake:proximity_properties>
        <drake:mesh_resolution_hint value="0.04"/>
        <drake:compliant_hydroelastic/>
        <drake:hydroelastic_modulus value="1e6"/>
        <drake:hunt_crossley_dissipation value="5"/>
        <!-- Arbitrary guess at bubble friction properties -->
        <drake:mu_static value="0.8"/>
      </drake:proximity_properties>
    </collision>
  </link>
  <joint name="j2s7s300_joint_4_r" type="revolute">
    <parent link="j2s7s300_link_3_r"/>
    <child link="j2s7s300_link_4_r"/>
    <axis xyz="0 0 1"/>
    <limit effort="100" lower="0.523598775598" upper="5.75958653158" velocity="0.63"/>
    <origin rpy="1.57079632679 0 3.14159265359" xyz="0 0 -0.205"/>
    <dynamics damping="18.0" friction="0.0"/>
  </joint>
  <transmission name="j2s7s300_joint_4_r_trans">
    <type>transmission_interface/SimpleTransmission</type>
    <joint name="j2s7s300_joint_4_r">
      <hardwareInterface>EffortJointInterface</hardwareInterface>
    </joint>
    <actuator name="j2s7s300_joint_4_r_actuator">
      <hardwareInterface>EffortJointInterface</hardwareInterface>
    </actuator>
  </transmission>
  <link name="j2s7s300_link_5_r">
    <visual>
      <origin xyz="0 0 0.075"/>
      <geometry>
        <cylinder length="0.18" radius="0.085"/>
      </geometry>
      <material>
        <color rgba="0.812 0.039 0.039 1"/>
      </material>
    </visual>
    <visual>
      <geometry>
        <mesh filename="meshes/wrist_spherical_1.obj"/>
      </geometry>
      <material>
        <color rgba="0.812 0.039 0.039 1"/>
      </material>
    </visual>
    <visual>
      <geometry>
        <mesh filename="meshes/ring_small.obj"/>
      </geometry>
      <material>
        <color rgba="0.627451 0.627451 0.627451 1"/>
      </material>
    </visual>
    <collision>
      <geometry>
        <mesh filename="meshes/wrist_spherical_1.obj"/>
      </geometry>
    </collision>
    <inertial>
      <mass value="0.485"/>
      <origin xyz="0 0.0028848942 -0.063"/>
      <inertia ixx="0.0004321316048" ixy="0" ixz="0" iyy="0.0004321316048" iyz="0" izz="9.26e-05"/>
    </inertial>
  </link>
  <joint name="j2s7s300_joint_5_r" type="revolute">
    <parent link="j2s7s300_link_4_r"/>
    <child link="j2s7s300_link_5_r"/>
    <axis xyz="0 0 1"/>
    <limit effort="80" lower="0.18" upper="6.10" velocity="0.85"/>
    <origin rpy="-1.57079632679 0 3.14159265359" xyz="0 0.2073 -0.0114"/>
    <dynamics damping="3.0" friction="0.0"/>
  </joint>
  <transmission name="j2s7s300_joint_5_r_trans">
    <type>transmission_interface/SimpleTransmission</type>
    <joint name="j2s7s300_joint_5_r">
      <hardwareInterface>EffortJointInterface</hardwareInterface>
    </joint>
    <actuator name="j2s7s300_joint_5_r_actuator">
      <hardwareInterface>EffortJointInterface</hardwareInterface>
    </actuator>
  </transmission>
  <link name="j2s7s300_link_6_r">
    <visual>
      <geometry>
        <mesh filename="meshes/wrist_spherical_2.obj"/>
      </geometry>
      <material>
        <color rgba="0.812 0.039 0.039 1"/>
      </material>
    </visual>
    <visual>
      <geometry>
        <mesh filename="meshes/ring_small.obj"/>
      </geometry>
      <material>
        <color rgba="0.627451 0.627451 0.627451 1"/>
      </material>
    </visual>
    <collision>
      <geometry>
        <mesh filename="meshes/wrist_spherical_2.obj"/>
      </geometry>
    </collision>
    <inertial>
      <mass value="0.486"/>
      <origin xyz="0 0.063 -0.0028562765"/>
      <inertia ixx="0.0004321316048" ixy="0" ixz="0" iyy="9.26e-05" iyz="0" izz="0.0004321316048"/>
    </inertial>
  </link>
  <joint name="j2s7s300_joint_floatie_1.0_partA_r" type="fixed">
    <parent link="j2s7s300_link_6_r"/>
    <child link="floatie_1.0_on_link_6_r"/>
    <origin rpy="1.55 0 0" xyz="0 0.055 0.005"/>
  </joint>
  <link name="floatie_1.0_on_link_6_r">
    <inertial>
      <mass value="0.025"/>
    </inertial>
    <visual name='floatie_1.0_on_link_6_r_visual'>
      <origin rpy="0 0 0" xyz="0 0 0"/>
      <geometry>
        <cylinder length="0.045" radius="0.0775"/>
      </geometry>
      <material>
        <color rgba="0.812 0.039 0.039 1"/>
      </material>
    </visual>
    <collision name='floatie_1.0_on_link_6_r_visual'>
      <origin rpy="0 0 0" xyz="0 0 0"/>
      <geometry>
        <cylinder length="0.045" radius="0.0775"/>
      </geometry>
      <drake:proximity_properties>
        <drake:mesh_resolution_hint value="0.04"/>
        <drake:compliant_hydroelastic/>
        <drake:hydroelastic_modulus value="1e6"/>
        <drake:hunt_crossley_dissipation value="5"/>
        <!-- Arbitrary guess at bubble friction properties -->
        <drake:mu_static value="0.8"/>
      </drake:proximity_properties>
    </collision>
    <visual name='floatie_1.0_on_link_6_r_visual_2'>
      <origin rpy="0 0 0" xyz="0 0 0.06"/>
      <geometry>
        <sphere radius="0.0775"/>
      </geometry>
    </visual>
    <collision name='floatie_1.0_on_link_6_r_collision_2'>
      <origin rpy="0 0 0" xyz="0 0 0.045"/>
      <geometry>
        <sphere radius="0.0775"/>
      </geometry>
      <drake:proximity_properties>
        <drake:mesh_resolution_hint value="0.04"/>
        <drake:compliant_hydroelastic/>
        <drake:hydroelastic_modulus value="1e6"/>
        <drake:hunt_crossley_dissipation value="5"/>
        <!-- Arbitrary guess at bubble friction properties -->
        <drake:mu_static value="0.8"/>
      </drake:proximity_properties>
    </collision>
  </link>
 <joint name="j2s7s300_joint_floatie_1.0_partB_r" type="fixed">
    <parent link="j2s7s300_link_5_r"/>
    <child link="floatie_1.0_on_link_5_r"/>
    <origin rpy="0 0 0" xyz="0 0.005 -0.04"/>
  </joint>
 <link name="floatie_1.0_on_link_5_r">
    <inertial>
      <mass value="0.025"/>
    </inertial>
    <visual name='floatie_1.0_on_link_5_r_visual'>
      <origin rpy="0 0 0" xyz="0 0 0"/>
      <geometry>
        <cylinder length="0.045" radius="0.0775"/>
      </geometry>
      <material>
        <color rgba="0.812 0.039 0.039 1"/>
      </material>
    </visual>
    <collision name='floatie_1.0_on_link_5_r_collision'>
      <origin rpy="0 0 0" xyz="0 0 0"/>
      <geometry>
        <cylinder length="0.045" radius="0.0775"/>
      </geometry>
      <drake:proximity_properties>
        <drake:mesh_resolution_hint value="0.04"/>
        <drake:compliant_hydroelastic/>
        <drake:hydroelastic_modulus value="1e6"/>
        <drake:hunt_crossley_dissipation value="5"/>
        <!-- Arbitrary guess at bubble friction properties -->
        <drake:mu_static value="0.8"/>
      </drake:proximity_properties>
    </collision>
  </link>
  <joint name="j2s7s300_joint_6_r" type="revolute">
    <parent link="j2s7s300_link_5_r"/>
    <child link="j2s7s300_link_6_r"/>
    <axis xyz="0 0 1"/>
    <limit effort="80" lower="0.523598775598" upper="5.75958653158" velocity="0.85"/>
    <origin rpy="1.57079632679 0 3.14159265359" xyz="0 0 -0.10375"/>
    <dynamics damping="3.0" friction="0.0"/>
  </joint>
  <transmission name="j2s7s300_joint_6_r_trans">
    <type>transmission_interface/SimpleTransmission</type>
    <joint name="j2s7s300_joint_6_r">
      <hardwareInterface>EffortJointInterface</hardwareInterface>
    </joint>
    <actuator name="j2s7s300_joint_6_r_actuator">
      <hardwareInterface>EffortJointInterface</hardwareInterface>
    </actuator>
  </transmission>
  <link name="j2s7s300_link_7_r">
    <inertial>
      <mass value="0.01"/>
      <origin xyz="0 0 0"/>
      <inertia ixx="0.00001" ixy="0" ixz="0" iyy="0.00001" iyz="0" izz="0.00001"/>
    </inertial>
  </link>
  <joint name="j2s7s300_joint_7_r" type="revolute">
    <parent link="j2s7s300_link_6_r"/>
    <child link="j2s7s300_link_7_r"/>
    <axis xyz="0 0 1"/>
    <limit effort="80" lower="0.18" upper="6.10" velocity="0.85"/>
    <origin rpy="-1.57079632679 0 3.14159265359" xyz="0 0.10375 0"/>
    <dynamics damping="3.0" friction="0.0"/>
  </joint>
  <transmission name="j2s7s300_joint_7_r_trans">
    <type>transmission_interface/SimpleTransmission</type>
    <joint name="j2s7s300_joint_7_r">
      <hardwareInterface>EffortJointInterface</hardwareInterface>
    </joint>
    <actuator name="j2s7s300_joint_7_r_actuator">
      <hardwareInterface>EffortJointInterface</hardwareInterface>
    </actuator>
  </transmission>
  <link name="paw_link_r">
    <!-- Add the paw mount only for visual. -->
    <visual>
      <geometry>
        <mesh filename="meshes/MA-027-AY-0006_mount.obj"/>
      </geometry>
      <material>
        <color rgba="0.1788232 0.1788232 0.1788232 1"/>
      </material>
    </visual>
    <!-- Add the paw frame for visual and collision. -->
    <visual>
      <geometry>
        <mesh filename="meshes/MA-027-AY-0006_pawframe.obj"/>
      </geometry>
      <material>
        <color rgba="0.1788232 0.1788232 0.1788232 1"/>
      </material>
    </visual>
    <collision>
      <origin xyz="-0.03 0.06 0" rpy="1.57 0 0.9"/>
      <geometry>
        <cylinder length="0.055" radius="0.025"/>
      </geometry>
    </collision>
    <collision>
      <geometry>
        <mesh filename="meshes/MA-027-AY-0006_bubble35mm_coarse_250faces.vtk"/>
      </geometry>
      <drake:proximity_properties>
        <drake:mesh_resolution_hint value="0.04"/>
        <drake:compliant_hydroelastic/>
        <drake:hydroelastic_modulus value="1e6"/>
        <drake:hunt_crossley_dissipation value="5"/>
        <!-- Arbitrary guess at bubble friction properties -->
        <drake:mu_static value="0.9"/>
        <drake:mu_dynamic value="0.9"/>
      </drake:proximity_properties>
    </collision>
    <!-- Add the bubble mesh for visual and collision. -->
    <visual>
      <geometry>
        <mesh filename="meshes/MA-027-AY-0006_bubble35mm.obj"/>
      </geometry>
    </visual>
    <!-- Inertial values are approximate and calculated for a
         cylinder of radius 35mm, height 110mm and mass 270gms -->
    <inertial>
      <mass value="0.27"/>
      <origin xyz="-0.05 0.07 0" rpy="1.5707 0 0.85"/>
      <inertia ixx="0.000355" ixy="0" ixz="0" iyy="0.000355" iyz="0" izz="0.000165"/>
    </inertial>
  </link>
  <joint name='paw_joint_r' type='fixed'>
    <parent link='j2s7s300_link_7_r'/>
    <child link='paw_link_r'/>
    <origin rpy="-1.5705 0 2.0944" xyz="0 0 0"/>
  </joint>
  <link name="bubble_center_r">
    <inertial>
      <mass value="0.001"/>
      <origin xyz="0 0 0"/>
      <inertia ixx="0.000001" ixy="0" ixz="0" iyy="0.000001" iyz="0" izz="0.000001"/>
    </inertial>
  </link>
  <joint name='dummy_joint_r' type='fixed'>
    <parent link='paw_link_r'/>
    <child link='bubble_center_r'/>
    <origin rpy="0 0 0" xyz="-0.1295 0.0831 0.0017"/>
  </joint>
</robot>
